Workbook

Sheet CALENDARIO 2026
B1: BRIGADAS TELECO – CALENDARIO DE GUARDIAS 2026
B2: Leyenda: | C2: G | D2: Guardia | K2: F | L2: Festivo (sin guardia) | S2: V | T2: Vacaciones | AB2: Fin de semana | AI2: Evento Personal
D3: Festivo nacional | L3: Festivo Andalucía | T3: Festivo local Sevilla | AB3: RJ Jefatura
C6: OCTUBRE 2026 | AI6: Festivos del mes
B7: TELECO | C7: J | D7: V | E7: S | F7: D | G7: L | H7: M | I7: X | J7: J | K7: V | L7: S | M7: D | N7: L | O7: M | P7: X | Q7: J | R7: V | S7: S | T7: D | U7: L | V7: M | W7: X | X7: J | Y7: V | Z7: S | AA7: D | AB7: L | AC7: M | AD7: X | AE7: J | AF7: V | AG7: S | AI7: 12 Oct. | AJ7: Fiesta Nacional de España (Hispanidad) · Festivo nacional
C8: 1 | D8: 2 | E8: 3 | F8: 4 | G8: 5 | H8: 6 | I8: 7 | J8: 8 | K8: 9 | L8: 10 | M8: 11 | N8: 12 | O8: 13 | P8: 14 | Q8: 15 | R8: 16 | S8: 17 | T8: 18 | U8: 19 | V8: 20 | W8: 21 | X8: 22 | Y8: 23 | Z8: 24 | AA8: 25 | AB8: 26 | AC8: 27 | AD8: 28 | AE8: 29 | AF8: 30 | AG8: 31
B9: JAVI | G9: G | H9: G | I9: G | J9: G | K9: G | L9: G | M9: G | N9: F | U9: G | V9: G | W9: G | X9: G | Y9: G | Z9: G | AA9: G
B10: JOSE | C10: G | D10: G | E10: G | F10: G | N10: G | O10: G | P10: G | Q10: G | R10: G | S10: G | T10: G | AB10: G | AC10: G | AD10: G | AE10: G | AF10: G | AG10: G
B11: JOSE LUIS | C11: G | D11: G | E11: G | F11: G | G11: G | N11: F | AB11: G | AC11: G | AD11: G | AE11: G | AF11: G | AG11: G
B12: ALBERTO | N12: G | O12: G | P12: G | Q12: G | R12: G | S12: G | T12: G
B13: MOLINERO | H13: G | I13: G | J13: G | K13: G | L13: G | M13: G | N13: F | U13: G | V13: G | W13: G | X13: G | Y13: G | Z13: G | AA13: G
C15: NOVIEMBRE 2026 | AI15: Festivos del mes
B16: TELECO | C16: D | D16: L | E16: M | F16: X | G16: J | H16: V | I16: S | J16: D | K16: L | L16: M | M16: X | N16: J | O16: V | P16: S | Q16: D | R16: L | S16: M | T16: X | U16: J | V16: V | W16: S | X16: D | Y16: L | Z16: M | AA16: X | AB16: J | AC16: V | AD16: S | AE16: D | AF16: L | AI16: 2 Nov. | AJ16: Todos los Santos (trasladado del dom. 1) · Festivo Andalucía
C17: 1 | D17: 2 | E17: 3 | F17: 4 | G17: 5 | H17: 6 | I17: 7 | J17: 8 | K17: 9 | L17: 10 | M17: 11 | N17: 12 | O17: 13 | P17: 14 | Q17: 15 | R17: 16 | S17: 17 | T17: 18 | U17: 19 | V17: 20 | W17: 21 | X17: 22 | Y17: 23 | Z17: 24 | AA17: 25 | AB17: 26 | AC17: 27 | AD17: 28 | AE17: 29 | AF17: 30
B18: JAVI | D18: F | K18: G | L18: G | M18: G | N18: G | O18: G | P18: G | Q18: G | Y18: G | Z18: G | AA18: G | AB18: G | AC18: G | AD18: G | AE18: G
B19: JOSE | C19: G | D19: F | R19: G | S19: G | T19: G | U19: G | V19: G | W19: G | X19: G | AF19: G
B20: JOSE LUIS | C20: G | D20: F | K20: G | L20: G | M20: G | N20: G | O20: G | P20: G | Q20: G | AF20: G
B21: ALBERTO | D21: G | E21: G | F21: G | G21: G | H21: G | I21: G | J21: G | Y21: G | Z21: G | AA21: G | AB21: G | AC21: G | AD21: G | AE21: G
B22: MOLINERO | D22: G | E22: G | F22: G | G22: G | H22: G | I22: G | J22: G | R22: G | S22: G | T22: G | U22: G | V22: G | W22: G | X22: G
C24: DICIEMBRE 2026 | AI24: Festivos del mes
B25: TELECO | C25: M | D25: X | E25: J | F25: V | G25: S | H25: D | I25: L | J25: M | K25: X | L25: J | M25: V | N25: S | O25: D | P25: L | Q25: M | R25: X | S25: J | T25: V | U25: S | V25: D | W25: L | X25: M | Y25: X | Z25: J | AA25: V | AB25: S | AC25: D | AD25: L | AE25: M | AF25: X | AG25: J | AI25: 7 Dic. | AJ25: Día de la Constitución (trasladado del dom. 6) · Festivo Andalucía
C26: 1 | D26: 2 | E26: 3 | F26: 4 | G26: 5 | H26: 6 | I26: 7 | J26: 8 | K26: 9 | L26: 10 | M26: 11 | N26: 12 | O26: 13 | P26: 14 | Q26: 15 | R26: 16 | S26: 17 | T26: 18 | U26: 19 | V26: 20 | W26: 21 | X26: 22 | Y26: 23 | Z26: 24 | AA26: 25 | AB26: 26 | AC26: 27 | AD26: 28 | AE26: 29 | AF26: 30 | AG26: 31 | AI26: 8 Dic. | AJ26: Inmaculada Concepción · Festivo nacional
B27: JAVI | I27: F | J27: F | P27: G | Q27: G | R27: G | S27: G | T27: G | U27: G | V27: G | AA27: F | AD27: G | AE27: G | AF27: G | AG27: G | AI27: 24 Dic. | AJ27: Nochebuena · RJ Jefatura
B28: JOSE | C28: G | D28: G | E28: G | F28: G | G28: G | H28: G | I28: F | J28: F | W28: G | X28: G | Y28: G | Z28: G | AA28: G | AB28: G | AC28: G | AI28: 25 Dic. | AJ28: Natividad del Señor (Navidad) · Festivo nacional
B29: JOSE LUIS | C29: G | D29: G | E29: G | F29: G | G29: G | H29: G | I29: F | J29: F | P29: G | Q29: G | R29: G | S29: G | T29: G | U29: G | V29: G | AA29: F | AD29: G | AE29: G | AF29: G | AG29: G | AI29: 31 Dic. | AJ29: Nochevieja · RJ Jefatura
B30: ALBERTO | I30: G | J30: G | K30: G | L30: G | M30: G | N30: G | O30: G | T30: V | U30: V | V30: V | W30: V | X30: V | Y30: V | AA30: F | AB30: V | AC30: V | AD30: V | AE30: V | AF30: V
B31: MOLINERO | I31: G | J31: G | K31: G | L31: G | M31: G | N31: G | O31: G | W31: G | X31: G | Y31: G | Z31: G | AA31: G | AB31: G | AC31: G

Sheet CALENDARIO 2027
B1: BRIGADAS TELECO – CALENDARIO DE GUARDIAS 2027
B2: Leyenda: | C2: G | D2: Guardia | K2: F | L2: Festivo (sin guardia) | S2: V | T2: Vacaciones | AB2: Fin de semana
D3: Festivo nacional | L3: Festivo Andalucía | T3: Festivo local Sevilla | AB3: RJ Jefatura
C5: ENERO 2027 | AI5: Festivos del mes
B6: TELECO | C6: V | D6: S | E6: D | F6: L | G6: M | H6: X | I6: J | J6: V | K6: S | L6: D | M6: L | N6: M | O6: X | P6: J | Q6: V | R6: S | S6: D | T6: L | U6: M | V6: X | W6: J | X6: V | Y6: S | Z6: D | AA6: L | AB6: M | AC6: X | AD6: J | AE6: V | AF6: S | AG6: D | AI6: 1 Ene. | AJ6: Año Nuevo · Festivo nacional
C7: 1 | D7: 2 | E7: 3 | F7: 4 | G7: 5 | H7: 6 | I7: 7 | J7: 8 | K7: 9 | L7: 10 | M7: 11 | N7: 12 | O7: 13 | P7: 14 | Q7: 15 | R7: 16 | S7: 17 | T7: 18 | U7: 19 | V7: 20 | W7: 21 | X7: 22 | Y7: 23 | Z7: 24 | AA7: 25 | AB7: 26 | AC7: 27 | AD7: 28 | AE7: 29 | AF7: 30 | AG7: 31 | AI7: 6 Ene. | AJ7: Epifanía del Señor (Reyes) · Festivo nacional
B8: JAVI | C8: G | D8: G | E8: G | H8: F | M8: G | N8: G | O8: G | P8: G | Q8: G | R8: G | S8: G
B9: JOSE | C9: F | F9: G | G9: G | H9: G | I9: G | J9: G | K9: G | L9: G | AA9: G | AB9: G | AC9: G | AD9: G | AE9: G | AF9: G | AG9: G
B10: JOSE LUIS | C10: G | D10: G | E10: G | H10: F | T10: G | U10: G | V10: G | W10: G | X10: G | Y10: G | Z10: G
B11: ALBERTO | C11: F | F11: G | G11: G | H11: G | I11: G | J11: G | K11: G | L11: G | T11: G | U11: G | V11: G | W11: G | X11: G | Y11: G | Z11: G
B12: MOLINERO | C12: F | H12: F | M12: G | N12: G | O12: G | P12: G | Q12: G | R12: G | S12: G | AA12: G | AB12: G | AC12: G | AD12: G | AE12: G | AF12: G | AG12: G
C14: FEBRERO 2027
B15: TELECO | C15: L | D15: M | E15: X | F15: J | G15: V | H15: S | I15: D | J15: L | K15: M | L15: X | M15: J | N15: V | O15: S | P15: D | Q15: L | R15: M | S15: X | T15: J | U15: V | V15: S | W15: D | X15: L | Y15: M | Z15: X | AA15: J | AB15: V | AC15: S | AD15: D
C16: 1 | D16: 2 | E16: 3 | F16: 4 | G16: 5 | H16: 6 | I16: 7 | J16: 8 | K16: 9 | L16: 10 | M16: 11 | N16: 12 | O16: 13 | P16: 14 | Q16: 15 | R16: 16 | S16: 17 | T16: 18 | U16: 19 | V16: 20 | W16: 21 | X16: 22 | Y16: 23 | Z16: 24 | AA16: 25 | AB16: 26 | AC16: 27 | AD16: 28
B17: JAVI | C17: G | D17: G | E17: G | F17: G | G17: G | H17: G | I17: G | Q17: G | R17: G | S17: G | T17: G | U17: G | V17: G | W17: G
B18: JOSE | J18: G | K18: G | L18: G | M18: G | N18: G | O18: G | P18: G
B19: JOSE LUIS | J19: G | K19: G | L19: G | M19: G | N19: G | O19: G | P19: G | X19: G | Y19: G | Z19: G | AA19: G | AB19: G | AC19: G | AD19: G
B20: ALBERTO | C20: G | D20: G | E20: G | F20: G | G20: G | H20: G | I20: G | X20: G | Y20: G | Z20: G | AA20: G | AB20: G | AC20: G | AD20: G
B21: MOLINERO | Q21: G | R21: G | S21: G | T21: G | U21: G | V21: G | W21: G
C23: MARZO 2027 | AI23: Festivos del mes
B24: TELECO | C24: L | D24: M | E24: X | F24: J | G24: V | H24: S | I24: D | J24: L | K24: M | L24: X | M24: J | N24: V | O24: S | P24: D | Q24: L | R24: M | S24: X | T24: J | U24: V | V24: S | W24: D | X24: L | Y24: M | Z24: X | AA24: J | AB24: V | AC24: S | AD24: D | AE24: L | AF24: M | AG24: X | AI24: 1 Mar. | AJ24: Día de Andalucía (trasladado del dom. 28/02) · Festivo Andalucía
C25: 1 | D25: 2 | E25: 3 | F25: 4 | G25: 5 | H25: 6 | I25: 7 | J25: 8 | K25: 9 | L25: 10 | M25: 11 | N25: 12 | O25: 13 | P25: 14 | Q25: 15 | R25: 16 | S25: 17 | T25: 18 | U25: 19 | V25: 20 | W25: 21 | X25: 22 | Y25: 23 | Z25: 24 | AA25: 25 | AB25: 26 | AC25: 27 | AD25: 28 | AE25: 29 | AF25: 30 | AG25: 31 | AI25: 25 Mar. | AJ25: Jueves Santo · Festivo Andalucía
B26: JAVI | C26: G | D26: G | E26: G | F26: G | G26: G | H26: G | I26: G | X26: G | Y26: G | Z26: G | AA26: G | AB26: G | AC26: G | AD26: G | AI26: 26 Mar. | AJ26: Viernes Santo · Festivo nacional
B27: JOSE | C27: G | D27: G | E27: G | F27: G | G27: G | H27: G | I27: G | Q27: G | R27: G | S27: G | T27: G | U27: G | V27: G | W27: G | AA27: F | AB27: F | AE27: G | AF27: G | AG27: G
B28: JOSE LUIS | C28: F | J28: G | K28: G | L28: G | M28: G | N28: G | O28: G | P28: G | AA28: F | AB28: F | AE28: G | AF28: G | AG28: G
B29: ALBERTO | C29: F | Q29: G | R29: G | S29: G | T29: G | U29: G | V29: G | W29: G | AA29: F | AB29: F
B30: MOLINERO | C30: F | J30: G | K30: G | L30: G | M30: G | N30: G | O30: G | P30: G | X30: G | Y30: G | Z30: G | AA30: G | AB30: G | AC30: G | AD30: G
C32: ABRIL 2027 | AI32: Festivos del mes
B33: TELECO | C33: J | D33: V | E33: S | F33: D | G33: L | H33: M | I33: X | J33: J | K33: V | L33: S | M33: D | N33: L | O33: M | P33: X | Q33: J | R33: V | S33: S | T33: D | U33: L | V33: M | W33: X | X33: J | Y33: V | Z33: S | AA33: D | AB33: L | AC33: M | AD33: X | AE33: J | AF33: V | AI33: 14 Abr. | AJ33: Miércoles de Feria · Festivo local Sevilla
C34: 1 | D34: 2 | E34: 3 | F34: 4 | G34: 5 | H34: 6 | I34: 7 | J34: 8 | K34: 9 | L34: 10 | M34: 11 | N34: 12 | O34: 13 | P34: 14 | Q34: 15 | R34: 16 | S34: 17 | T34: 18 | U34: 19 | V34: 20 | W34: 21 | X34: 22 | Y34: 23 | Z34: 24 | AA34: 25 | AB34: 26 | AC34: 27 | AD34: 28 | AE34: 29 | AF34: 30
B35: JAVI | N35: G | O35: G | P35: G | Q35: G | R35: G | S35: G | T35: G
B36: JOSE | C36: G | D36: G | E36: G | F36: G | P36: F | U36: G | V36: G | W36: G | X36: G | Y36: G | Z36: G | AA36: G
B37: JOSE LUIS | C37: G | D37: G | E37: G | F37: G | N37: G | O37: G | P37: G | Q37: G | R37: G | S37: G | T37: G | AB37: G | AC37: G | AD37: G | AE37: G | AF37: G
B38: ALBERTO | G38: G | H38: G | I38: G | J38: G | K38: G | L38: G | M38: G | P38: F | U38: G | V38: G | W38: G | X38: G | Y38: G | Z38: G | AA38: G
B39: MOLINERO | G39: G | H39: G | I39: G | J39: G | K39: G | L39: G | M39: G | P39: F | AB39: G | AC39: G | AD39: G | AE39: G | AF39: G
C41: MAYO 2027 | AI41: Festivos del mes
B42: TELECO | C42: S | D42: D | E42: L | F42: M | G42: X | H42: J | I42: V | J42: S | K42: D | L42: L | M42: M | N42: X | O42: J | P42: V | Q42: S | R42: D | S42: L | T42: M | U42: X | V42: J | W42: V | X42: S | Y42: D | Z42: L | AA42: M | AB42: X | AC42: J | AD42: V | AE42: S | AF42: D | AG42: L | AI42: 1 May. | AJ42: Fiesta del Trabajo · Festivo nacional
C43: 1 | D43: 2 | E43: 3 | F43: 4 | G43: 5 | H43: 6 | I43: 7 | J43: 8 | K43: 9 | L43: 10 | M43: 11 | N43: 12 | O43: 13 | P43: 14 | Q43: 15 | R43: 16 | S43: 17 | T43: 18 | U43: 19 | V43: 20 | W43: 21 | X43: 22 | Y43: 23 | Z43: 24 | AA43: 25 | AB43: 26 | AC43: 27 | AD43: 28 | AE43: 29 | AF43: 30 | AG43: 31 | AI43: 27 May. | AJ43: Corpus Christi · Festivo local Sevilla
B44: JAVI | C44: F | E44: G | F44: G | G44: G | H44: G | I44: G | J44: G | K44: G | S44: G | T44: G | U44: G | V44: G | W44: G | X44: G | Y44: G | AC44: F
B45: JOSE | C45: F | L45: G | M45: G | N45: G | O45: G | P45: G | Q45: G | R45: G | Z45: G | AA45: G | AB45: G | AC45: G | AD45: G | AE45: G | AF45: G
...

Sheet GUARDIAS
B2: DÍAS DE GUARDIA | C2: OCT 26 | D2: NOV 26 | E2: DIC 26 | F2: TOTAL 2026 | G2: ENE 27 | H2: FEB 27 | I2: MAR 27 | J2: ABR 27 | K2: MAY 27 | L2: JUN 27 | M2: JUL 27 | N2: AGO 27 | O2: SEP 27 | P2: OCT 27 | Q2: NOV 27 | R2: DIC 27 | S2: TOTAL 2027 | T2: TOTAL | U2: FESTIVOS TRABAJADOS | V2: DIF. vs MEDIA
B3: JAVI | C3: =COUNTIF('CALENDARIO 2026'!$C$9:$AG$9,"*G*") -> 14 | D3: =COUNTIF('CALENDARIO 2026'!$C$18:$AF$18,"*G*") -> 14 | E3: =COUNTIF('CALENDARIO 2026'!$C$27:$AG$27,"*G*") -> 11 | F3: =SUM(C3:E3) -> 39 | G3: =COUNTIF('CALENDARIO 2027'!$C$8:$AG$8,"*G*") -> 10 | H3: =COUNTIF('CALENDARIO 2027'!$C$17:$AD$17,"*G*") -> 14 | I3: =COUNTIF('CALENDARIO 2027'!$C$26:$AG$26,"*G*") -> 14 | J3: =COUNTIF('CALENDARIO 2027'!$C$35:$AF$35,"*G*") -> 7 | K3: =COUNTIF('CALENDARIO 2027'!$C$44:$AG$44,"*G*") -> 14 | L3: =COUNTIF('CALENDARIO 2027'!$C$53:$AF$53,"*G*") -> 10 | M3: =COUNTIF('CALENDARIO 2027'!$C$62:$AG$62,"*G*") -> 11 | N3: =COUNTIF('CALENDARIO 2027'!$C$71:$AG$71,"*G*") -> 14 | O3: =COUNTIF('CALENDARIO 2027'!$C$80:$AF$80,"*G*") -> 14 | P3: =COUNTIF('CALENDARIO 2027'!$C$89:$AG$89,"*G*") -> 14 | Q3: =COUNTIF('CALENDARIO 2027'!$C$98:$AF$98,"*G*") -> 9 | R3: =COUNTIF('CALENDARIO 2027'!$C$107:$AG$107,"*G*") -> 12 | S3: =SUM(G3:R3) -> 143 | T3: =F3+S3 -> 182 | U3: =FESTIVOS!J3+FESTIVOS!S11 -> 9 | V3: =T3-AVERAGE($T$3:$T$7) -> -0.8
B4: JOSE | C4: =COUNTIF('CALENDARIO 2026'!$C$10:$AG$10,"*G*") -> 17 | D4: =COUNTIF('CALENDARIO 2026'!$C$19:$AF$19,"*G*") -> 9 | E4: =COUNTIF('CALENDARIO 2026'!$C$28:$AG$28,"*G*") -> 13 | F4: =SUM(C4:E4) -> 39 | G4: =COUNTIF('CALENDARIO 2027'!$C$9:$AG$9,"*G*") -> 14 | H4: =COUNTIF('CALENDARIO 2027'!$C$18:$AD$18,"*G*") -> 7 | I4: =COUNTIF('CALENDARIO 2027'!$C$27:$AG$27,"*G*") -> 17 | J4: =COUNTIF('CALENDARIO 2027'!$C$36:$AF$36,"*G*") -> 11 | K4: =COUNTIF('CALENDARIO 2027'!$C$45:$AG$45,"*G*") -> 14 | L4: =COUNTIF('CALENDARIO 2027'!$C$54:$AF$54,"*G*") -> 10 | M4: =COUNTIF('CALENDARIO 2027'!$C$63:$AG$63,"*G*") -> 11 | N4: =COUNTIF('CALENDARIO 2027'!$C$72:$AG$72,"*G*") -> 14 | O4: =COUNTIF('CALENDARIO 2027'!$C$81:$AF$81,"*G*") -> 11 | P4: =COUNTIF('CALENDARIO 2027'!$C$90:$AG$90,"*G*") -> 10 | Q4: =COUNTIF('CALENDARIO 2027'!$C$99:$AF$99,"*G*") -> 14 | R4: =COUNTIF('CALENDARIO 2027'!$C$108:$AG$108,"*G*") -> 12 | S4: =SUM(G4:R4) -> 145 | T4: =F4+S4 -> 184 | U4: =FESTIVOS!J4+FESTIVOS!S12 -> 10 | V4: =T4-AVERAGE($T$3:$T$7) -> 1.2
B5: JOSE LUIS | C5: =COUNTIF('CALENDARIO 2026'!$C$11:$AG$11,"*G*") -> 11 | D5: =COUNTIF('CALENDARIO 2026'!$C$20:$AF$20,"*G*") -> 9 | E5: =COUNTIF('CALENDARIO 2026'!$C$29:$AG$29,"*G*") -> 17 | F5: =SUM(C5:E5) -> 37 | G5: =COUNTIF('CALENDARIO 2027'!$C$10:$AG$10,"*G*") -> 10 | H5: =COUNTIF('CALENDARIO 2027'!$C$19:$AD$19,"*G*") -> 14 | I5: =COUNTIF('CALENDARIO 2027'!$C$28:$AG$28,"*G*") -> 10 | J5: =COUNTIF('CALENDARIO 2027'!$C$37:$AF$37,"*G*") -> 16 | K5: =COUNTIF('CALENDARIO 2027'!$C$46:$AG$46,"*G*") -> 10 | L5: =COUNTIF('CALENDARIO 2027'!$C$55:$AF$55,"*G*") -> 13 | M5: =COUNTIF('CALENDARIO 2027'!$C$64:$AG$64,"*G*") -> 14 | N5: =COUNTIF('CALENDARIO 2027'!$C$73:$AG$73,"*G*") -> 14 | O5: =COUNTIF('CALENDARIO 2027'!$C$82:$AF$82,"*G*") -> 11 | P5: =COUNTIF('CALENDARIO 2027'!$C$91:$AG$91,"*G*") -> 10 | Q5: =COUNTIF('CALENDARIO 2027'!$C$100:$AF$100,"*G*") -> 14 | R5: =COUNTIF('CALENDARIO 2027'!$C$109:$AG$109,"*G*") -> 14 | S5: =SUM(G5:R5) -> 150 | T5: =F5+S5 -> 187 | U5: =FESTIVOS!J5+FESTIVOS!S13 -> 9 | V5: =T5-AVERAGE($T$3:$T$7) -> 4.2
B6: ALBERTO | C6: =COUNTIF('CALENDARIO 2026'!$C$12:$AG$12,"*G*") -> 7 | D6: =COUNTIF('CALENDARIO 2026'!$C$21:$AF$21,"*G*") -> 14 | E6: =COUNTIF('CALENDARIO 2026'!$C$30:$AG$30,"*G*") -> 7 | F6: =SUM(C6:E6) -> 28 | G6: =COUNTIF('CALENDARIO 2027'!$C$11:$AG$11,"*G*") -> 14 | H6: =COUNTIF('CALENDARIO 2027'!$C$20:$AD$20,"*G*") -> 14 | I6: =COUNTIF('CALENDARIO 2027'!$C$29:$AG$29,"*G*") -> 7 | J6: =COUNTIF('CALENDARIO 2027'!$C$38:$AF$38,"*G*") -> 14 | K6: =COUNTIF('CALENDARIO 2027'!$C$47:$AG$47,"*G*") -> 14 | L6: =COUNTIF('CALENDARIO 2027'!$C$56:$AF$56,"*G*") -> 14 | M6: =COUNTIF('CALENDARIO 2027'!$C$65:$AG$65,"*G*") -> 13 | N6: =COUNTIF('CALENDARIO 2027'!$C$74:$AG$74,"*G*") -> 10 | O6: =COUNTIF('CALENDARIO 2027'!$C$83:$AF$83,"*G*") -> 12 | P6: =COUNTIF('CALENDARIO 2027'!$C$92:$AG$92,"*G*") -> 14 | Q6: =COUNTIF('CALENDARIO 2027'!$C$101:$AF$101,"*G*") -> 14 | R6: =COUNTIF('CALENDARIO 2027'!$C$110:$AG$110,"*G*") -> 12 | S6: =SUM(G6:R6) -> 152 | T6: =F6+S6 -> 180 | U6: =FESTIVOS!J6+FESTIVOS!S14 -> 10 | V6: =T6-AVERAGE($T$3:$T$7) -> -2.8
B7: MOLINERO | C7: =COUNTIF('CALENDARIO 2026'!$C$13:$AG$13,"*G*") -> 13 | D7: =COUNTIF('CALENDARIO 2026'!$C$22:$AF$22,"*G*") -> 14 | E7: =COUNTIF('CALENDARIO 2026'!$C$31:$AG$31,"*G*") -> 14 | F7: =SUM(C7:E7) -> 41 | G7: =COUNTIF('CALENDARIO 2027'!$C$12:$AG$12,"*G*") -> 14 | H7: =COUNTIF('CALENDARIO 2027'!$C$21:$AD$21,"*G*") -> 7 | I7: =COUNTIF('CALENDARIO 2027'!$C$30:$AG$30,"*G*") -> 14 | J7: =COUNTIF('CALENDARIO 2027'!$C$39:$AF$39,"*G*") -> 12 | K7: =COUNTIF('CALENDARIO 2027'!$C$48:$AG$48,"*G*") -> 10 | L7: =COUNTIF('CALENDARIO 2027'!$C$57:$AF$57,"*G*") -> 13 | M7: =COUNTIF('CALENDARIO 2027'!$C$66:$AG$66,"*G*") -> 13 | N7: =COUNTIF('CALENDARIO 2027'!$C$75:$AG$75,"*G*") -> 10 | O7: =COUNTIF('CALENDARIO 2027'!$C$84:$AF$84,"*G*") -> 12 | P7: =COUNTIF('CALENDARIO 2027'!$C$93:$AG$93,"*G*") -> 14 | Q7: =COUNTIF('CALENDARIO 2027'!$C$102:$AF$102,"*G*") -> 9 | R7: =COUNTIF('CALENDARIO 2027'!$C$111:$AG$111,"*G*") -> 12 | S7: =SUM(G7:R7) -> 140 | T7: =F7+S7 -> 181 | U7: =FESTIVOS!J7+FESTIVOS!S15 -> 8 | V7: =T7-AVERAGE($T$3:$T$7) -> -1.8
B9: Cuenta las celdas con "G" de cada fila del calendario (incluye el histórico de sep. y 1–18 oct. del modelo original).
B10: Diferencia final de unos días: se debe a ese histórico desigual y a que la última semana de 2027 termina el viernes 31.
B12: CRUCES (semanas juntos) | C12: JAVI | D12: JOSE | E12: JOSE LUIS | F12: ALBERTO | G12: MOLINERO
B13: JAVI | C13: – | D13: =SUMPRODUCT(SEMANAS!$H$3:$H$65,SEMANAS!$I$3:$I$65) -> 5 | E13: =SUMPRODUCT(SEMANAS!$H$3:$H$65,SEMANAS!$J$3:$J$65) -> 7 | F13: =SUMPRODUCT(SEMANAS!$H$3:$H$65,SEMANAS!$K$3:$K$65) -> 6 | G13: =SUMPRODUCT(SEMANAS!$H$3:$H$65,SEMANAS!$L$3:$L$65) -> 7
B14: JOSE | C14: =SUMPRODUCT(SEMANAS!$I$3:$I$65,SEMANAS!$H$3:$H$65) -> 5 | D14: – | E14: =SUMPRODUCT(SEMANAS!$I$3:$I$65,SEMANAS!$J$3:$J$65) -> 7 | F14: =SUMPRODUCT(SEMANAS!$I$3:$I$65,SEMANAS!$K$3:$K$65) -> 7 | G14: =SUMPRODUCT(SEMANAS!$I$3:$I$65,SEMANAS!$L$3:$L$65) -> 6
B15: JOSE LUIS | C15: =SUMPRODUCT(SEMANAS!$J$3:$J$65,SEMANAS!$H$3:$H$65) -> 7 | D15: =SUMPRODUCT(SEMANAS!$J$3:$J$65,SEMANAS!$I$3:$I$65) -> 7 | E15: – | F15: =SUMPRODUCT(SEMANAS!$J$3:$J$65,SEMANAS!$K$3:$K$65) -> 6 | G15: =SUMPRODUCT(SEMANAS!$J$3:$J$65,SEMANAS!$L$3:$L$65) -> 6
B16: ALBERTO | C16: =SUMPRODUCT(SEMANAS!$K$3:$K$65,SEMANAS!$H$3:$H$65) -> 6 | D16: =SUMPRODUCT(SEMANAS!$K$3:$K$65,SEMANAS!$I$3:$I$65) -> 7 | E16: =SUMPRODUCT(SEMANAS!$K$3:$K$65,SEMANAS!$J$3:$J$65) -> 6 | F16: – | G16: =SUMPRODUCT(SEMANAS!$K$3:$K$65,SEMANAS!$L$3:$L$65) -> 6
B17: MOLINERO | C17: =SUMPRODUCT(SEMANAS!$L$3:$L$65,SEMANAS!$H$3:$H$65) -> 7 | D17: =SUMPRODUCT(SEMANAS!$L$3:$L$65,SEMANAS!$I$3:$I$65) -> 6 | E17: =SUMPRODUCT(SEMANAS!$L$3:$L$65,SEMANAS!$J$3:$J$65) -> 6 | F17: =SUMPRODUCT(SEMANAS!$L$3:$L$65,SEMANAS!$K$3:$K$65) -> 6 | G17: –
B19: Número de semanas que cada pareja coincide de guardia desde el 19/10/2026 hasta el 31/12/2027 (10 parejas posibles; lo ideal es 6–7 cada una).

Sheet FESTIVOS
B2: FESTIVOS 2026 | C2: 12/10 Hispanidad | D2: 02/11 Todos los Santos | E2: 07/12 Día de la Constitución | F2: 08/12 Inmaculada Concepción | G2: 24/12 Nochebuena | H2: 25/12 Navidad | I2: 31/12 Nochevieja | J2: TOTAL 2026
B3: JAVI | C3: =IF('CALENDARIO 2026'!N9="G",1,"") | D3: =IF('CALENDARIO 2026'!D18="G",1,"") | E3: =IF('CALENDARIO 2026'!I27="G",1,"") | F3: =IF('CALENDARIO 2026'!J27="G",1,"") | G3: =IF('CALENDARIO 2026'!Z27="G",1,"") | H3: =IF('CALENDARIO 2026'!AA27="G",1,"") | I3: =IF('CALENDARIO 2026'!AG27="G",1,"") -> 1 | J3: =SUM(C3:I3) -> 1
B4: JOSE | C4: =IF('CALENDARIO 2026'!N10="G",1,"") -> 1 | D4: =IF('CALENDARIO 2026'!D19="G",1,"") | E4: =IF('CALENDARIO 2026'!I28="G",1,"") | F4: =IF('CALENDARIO 2026'!J28="G",1,"") | G4: =IF('CALENDARIO 2026'!Z28="G",1,"") -> 1 | H4: =IF('CALENDARIO 2026'!AA28="G",1,"") -> 1 | I4: =IF('CALENDARIO 2026'!AG28="G",1,"") | J4: =SUM(C4:I4) -> 3
B5: JOSE LUIS | C5: =IF('CALENDARIO 2026'!N11="G",1,"") | D5: =IF('CALENDARIO 2026'!D20="G",1,"") | E5: =IF('CALENDARIO 2026'!I29="G",1,"") | F5: =IF('CALENDARIO 2026'!J29="G",1,"") | G5: =IF('CALENDARIO 2026'!Z29="G",1,"") | H5: =IF('CALENDARIO 2026'!AA29="G",1,"") | I5: =IF('CALENDARIO 2026'!AG29="G",1,"") -> 1 | J5: =SUM(C5:I5) -> 1
B6: ALBERTO | C6: =IF('CALENDARIO 2026'!N12="G",1,"") -> 1 | D6: =IF('CALENDARIO 2026'!D21="G",1,"") -> 1 | E6: =IF('CALENDARIO 2026'!I30="G",1,"") -> 1 | F6: =IF('CALENDARIO 2026'!J30="G",1,"") -> 1 | G6: =IF('CALENDARIO 2026'!Z30="G",1,"") | H6: =IF('CALENDARIO 2026'!AA30="G",1,"") | I6: =IF('CALENDARIO 2026'!AG30="G",1,"") | J6: =SUM(C6:I6) -> 4
B7: MOLINERO | C7: =IF('CALENDARIO 2026'!N13="G",1,"") | D7: =IF('CALENDARIO 2026'!D22="G",1,"") -> 1 | E7: =IF('CALENDARIO 2026'!I31="G",1,"") -> 1 | F7: =IF('CALENDARIO 2026'!J31="G",1,"") -> 1 | G7: =IF('CALENDARIO 2026'!Z31="G",1,"") -> 1 | H7: =IF('CALENDARIO 2026'!AA31="G",1,"") -> 1 | I7: =IF('CALENDARIO 2026'!AG31="G",1,"") | J7: =SUM(C7:I7) -> 5
B10: FESTIVOS 2027 | C10: 01/01 Año Nuevo | D10: 06/01 Epifanía del Señor | E10: 01/03 Día de Andalucía | F10: 25/03 Jueves Santo | G10: 26/03 Viernes Santo | H10: 14/04 Miércoles de Feria | I10: 01/05 Fiesta del Trabajo | J10: 27/05 Corpus Christi | K10: 16/08 Asunción de la Virgen | L10: 12/10 Hispanidad | M10: 01/11 Todos los Santos | N10: 06/12 Día de la Constitución | O10: 08/12 Inmaculada Concepción | P10: 24/12 Nochebuena | Q10: 25/12 Navidad | R10: 31/12 Nochevieja | S10: TOTAL 2027 | T10: TOTAL 2026 2027
B11: JAVI | C11: =IF('CALENDARIO 2027'!C8="G",1,"") -> 1 | D11: =IF('CALENDARIO 2027'!H8="G",1,"") | E11: =IF('CALENDARIO 2027'!C26="G",1,"") -> 1 | F11: =IF('CALENDARIO 2027'!AA26="G",1,"") -> 1 | G11: =IF('CALENDARIO 2027'!AB26="G",1,"") -> 1 | H11: =IF('CALENDARIO 2027'!P35="G",1,"") -> 1 | I11: =IF('CALENDARIO 2027'!C44="G",1,"") | J11: =IF('CALENDARIO 2027'!AC44="G",1,"") | K11: =IF('CALENDARIO 2027'!R71="G",1,"") | L11: =IF('CALENDARIO 2027'!N89="G",1,"") -> 1 | M11: =IF('CALENDARIO 2027'!C98="G",1,"") | N11: =IF('CALENDARIO 2027'!H107="G",1,"") | O11: =IF('CALENDARIO 2027'!J107="G",1,"") | P11: =IF('CALENDARIO 2027'!Z107="G",1,"") -> 1 | Q11: =IF('CALENDARIO 2027'!AA107="G",1,"") -> 1 | R11: =IF('CALENDARIO 2027'!AG107="G",1,"") | S11: =SUM(C11:R11) -> 8 | T11: =SUM(J3,S11) -> 9
B12: JOSE | C12: =IF('CALENDARIO 2027'!C9="G",1,"") | D12: =IF('CALENDARIO 2027'!H9="G",1,"") -> 1 | E12: =IF('CALENDARIO 2027'!C27="G",1,"") -> 1 | F12: =IF('CALENDARIO 2027'!AA27="G",1,"") | G12: =IF('CALENDARIO 2027'!AB27="G",1,"") | H12: =IF('CALENDARIO 2027'!P36="G",1,"") | I12: =IF('CALENDARIO 2027'!C45="G",1,"") | J12: =IF('CALENDARIO 2027'!AC45="G",1,"") -> 1 | K12: =IF('CALENDARIO 2027'!R72="G",1,"") -> 1 | L12: =IF('CALENDARIO 2027'!N90="G",1,"") -> 1 | M12: =IF('CALENDARIO 2027'!C99="G",1,"") -> 1 | N12: =IF('CALENDARIO 2027'!H108="G",1,"") | O12: =IF('CALENDARIO 2027'!J108="G",1,"") | P12: =IF('CALENDARIO 2027'!Z108="G",1,"") | Q12: =IF('CALENDARIO 2027'!AA108="G",1,"") | R12: =IF('CALENDARIO 2027'!AG108="G",1,"") -> 1 | S12: =SUM(C12:R12) -> 7 | T12: =SUM(J4,S12) -> 10
B13: JOSE LUIS | C13: =IF('CALENDARIO 2027'!C10="G",1,"") -> 1 | D13: =IF('CALENDARIO 2027'!H10="G",1,"") | E13: =IF('CALENDARIO 2027'!C28="G",1,"") | F13: =IF('CALENDARIO 2027'!AA28="G",1,"") | G13: =IF('CALENDARIO 2027'!AB28="G",1,"") | H13: =IF('CALENDARIO 2027'!P37="G",1,"") -> 1 | I13: =IF('CALENDARIO 2027'!C46="G",1,"") -> 1 | J13: =IF('CALENDARIO 2027'!AC46="G",1,"") | K13: =IF('CALENDARIO 2027'!R73="G",1,"") | L13: =IF('CALENDARIO 2027'!N91="G",1,"") | M13: =IF('CALENDARIO 2027'!C100="G",1,"") -> 1 | N13: =IF('CALENDARIO 2027'!H109="G",1,"") -> 1 | O13: =IF('CALENDARIO 2027'!J109="G",1,"") -> 1 | P13: =IF('CALENDARIO 2027'!Z109="G",1,"") -> 1 | Q13: =IF('CALENDARIO 2027'!AA109="G",1,"") -> 1 | R13: =IF('CALENDARIO 2027'!AG109="G",1,"") | S13: =SUM(C13:R13) -> 8 | T13: =SUM(J5,S13) -> 9
B14: ALBERTO | C14: =IF('CALENDARIO 2027'!C11="G",1,"") | D14: =IF('CALENDARIO 2027'!H11="G",1,"") -> 1 | E14: =IF('CALENDARIO 2027'!C29="G",1,"") | F14: =IF('CALENDARIO 2027'!AA29="G",1,"") | G14: =IF('CALENDARIO 2027'!AB29="G",1,"") | H14: =IF('CALENDARIO 2027'!P38="G",1,"") | I14: =IF('CALENDARIO 2027'!C47="G",1,"") | J14: =IF('CALENDARIO 2027'!AC47="G",1,"") -> 1 | K14: =IF('CALENDARIO 2027'!R74="G",1,"") -> 1 | L14: =IF('CALENDARIO 2027'!N92="G",1,"") | M14: =IF('CALENDARIO 2027'!C101="G",1,"") | N14: =IF('CALENDARIO 2027'!H110="G",1,"") -> 1 | O14: =IF('CALENDARIO 2027'!J110="G",1,"") -> 1 | P14: =IF('CALENDARIO 2027'!Z110="G",1,"") | Q14: =IF('CALENDARIO 2027'!AA110="G",1,"") | R14: =IF('CALENDARIO 2027'!AG110="G",1,"") -> 1 | S14: =SUM(C14:R14) -> 6 | T14: =SUM(J6,S14) -> 10
B15: MOLINERO | C15: =IF('CALENDARIO 2027'!C12="G",1,"") | D15: =IF('CALENDARIO 2027'!H12="G",1,"") | E15: =IF('CALENDARIO 2027'!C30="G",1,"") | F15: =IF('CALENDARIO 2027'!AA30="G",1,"") -> 1 | G15: =IF('CALENDARIO 2027'!AB30="G",1,"") -> 1 | H15: =IF('CALENDARIO 2027'!P39="G",1,"") | I15: =IF('CALENDARIO 2027'!C48="G",1,"") -> 1 | J15: =IF('CALENDARIO 2027'!AC48="G",1,"") | K15: =IF('CALENDARIO 2027'!R75="G",1,"") | L15: =IF('CALENDARIO 2027'!N93="G",1,"") | M15: =IF('CALENDARIO 2027'!C102="G",1,"") | N15: =IF('CALENDARIO 2027'!H111="G",1,"") | O15: =IF('CALENDARIO 2027'!J111="G",1,"") | P15: =IF('CALENDARIO 2027'!Z111="G",1,"") | Q15: =IF('CALENDARIO 2027'!AA111="G",1,"") | R15: =IF('CALENDARIO 2027'!AG111="G",1,"") | S15: =SUM(C15:R15) -> 3 | T15: =SUM(J7,S15) -> 8
B18: Cuenta 1 cuando la persona tiene "G" ese día en el calendario. Fuentes: Decreto Junta de Andalucía 2026 y Decreto 84/2026 (BOJA, calendario 2027); fiestas locales de Sevilla 2027 aprobadas por el Pleno municipal. Los días RJ Jefatura (24 y 31 dic) se toman del modelo original y se asumen iguales en 2027.

Sheet SEMANAS
H1: Auxiliar: 1 = de guardia esa semana (lo usa la tabla de cruces)
B2: SEM. | C2: DESDE (L) | D2: HASTA (D) | E2: EN GUARDIA | F2: FESTIVOS EN LA SEMANA | H2: JAVI | I2: JOSE | J2: JOSE LUIS | K2: ALBERTO | L2: MOLINERO
B3: 1 | C3: 46314 | D3: 46320 | E3: =LEFT(IF('CALENDARIO 2026'!U9="G","JAVI · ","")&IF('CALENDARIO 2026'!U10="G","JOSE · ","")&IF('CALENDARIO 2026'!U11="G","JOSE LUIS · ","")&IF('CALENDARIO 2026'!U12="G","ALBERTO · ","")&IF('CALENDARIO 2026'!U13="G","MOLINERO · ",""),LEN(IF('CALENDARIO 2026'!U9="G","JAVI · ","")&IF('CALENDARIO 2026'!U10="G","JOSE · ","")&IF('CALENDARIO 2026'!U11="G","JOSE LUIS · ","")&IF('CALENDARIO 2026'!U12="G","ALBERTO · ","")&IF('CALENDARIO 2026'!U13="G","MOLINERO · ",""))-3) -> JAVI · MOLINERO | H3: =IF('CALENDARIO 2026'!U9="G",1,0) -> 1 | I3: =IF('CALENDARIO 2026'!U10="G",1,0) -> 0 | J3: =IF('CALENDARIO 2026'!U11="G",1,0) -> 0 | K3: =IF('CALENDARIO 2026'!U12="G",1,0) -> 0 | L3: =IF('CALENDARIO 2026'!U13="G",1,0) -> 1
B4: 2 | C4: 46321 | D4: 46327 | E4: =LEFT(IF('CALENDARIO 2026'!AB9="G","JAVI · ","")&IF('CALENDARIO 2026'!AB10="G","JOSE · ","")&IF('CALENDARIO 2026'!AB11="G","JOSE LUIS · ","")&IF('CALENDARIO 2026'!AB12="G","ALBERTO · ","")&IF('CALENDARIO 2026'!AB13="G","MOLINERO · ",""),LEN(IF('CALENDARIO 2026'!AB9="G","JAVI · ","")&IF('CALENDARIO 2026'!AB10="G","JOSE · ","")&IF('CALENDARIO 2026'!AB11="G","JOSE LUIS · ","")&IF('CALENDARIO 2026'!AB12="G","ALBERTO · ","")&IF('CALENDARIO 2026'!AB13="G","MOLINERO · ",""))-3) -> JOSE · JOSE LUIS | H4: =IF('CALENDARIO 2026'!AB9="G",1,0) -> 0 | I4: =IF('CALENDARIO 2026'!AB10="G",1,0) -> 1 | J4: =IF('CALENDARIO 2026'!AB11="G",1,0) -> 1 | K4: =IF('CALENDARIO 2026'!AB12="G",1,0) -> 0 | L4: =IF('CALENDARIO 2026'!AB13="G",1,0) -> 0
B5: 3 | C5: 46328 | D5: 46334 | E5: =LEFT(IF('CALENDARIO 2026'!D18="G","JAVI · ","")&IF('CALENDARIO 2026'!D19="G","JOSE · ","")&IF('CALENDARIO 2026'!D20="G","JOSE LUIS · ","")&IF('CALENDARIO 2026'!D21="G","ALBERTO · ","")&IF('CALENDARIO 2026'!D22="G","MOLINERO · ",""),LEN(IF('CALENDARIO 2026'!D18="G","JAVI · ","")&IF('CALENDARIO 2026'!D19="G","JOSE · ","")&IF('CALENDARIO 2026'!D20="G","JOSE LUIS · ","")&IF('CALENDARIO 2026'!D21="G","ALBERTO · ","")&IF('CALENDARIO 2026'!D22="G","MOLINERO · ",""))-3) -> ALBERTO · MOLINERO | F5: 2/11 Todos los Santos (trasladado del dom. 1) | H5: =IF('CALENDARIO 2026'!D18="G",1,0) -> 0 | I5: =IF('CALENDARIO 2026'!D19="G",1,0) -> 0 | J5: =IF('CALENDARIO 2026'!D20="G",1,0) -> 0 | K5: =IF('CALENDARIO 2026'!D21="G",1,0) -> 1 | L5: =IF('CALENDARIO 2026'!D22="G",1,0) -> 1
B6: 4 | C6: 46335 | D6: 46341 | E6: =LEFT(IF('CALENDARIO 2026'!K18="G","JAVI · ","")&IF('CALENDARIO 2026'!K19="G","JOSE · ","")&IF('CALENDARIO 2026'!K20="G","JOSE LUIS · ","")&IF('CALENDARIO 2026'!K21="G","ALBERTO · ","")&IF('CALENDARIO 2026'!K22="G","MOLINERO · ",""),LEN(IF('CALENDARIO 2026'!K18="G","JAVI · ","")&IF('CALENDARIO 2026'!K19="G","JOSE · ","")&IF('CALENDARIO 2026'!K20="G","JOSE LUIS · ","")&IF('CALENDARIO 2026'!K21="G","ALBERTO · ","")&IF('CALENDARIO 2026'!K22="G","MOLINERO · ",""))-3) -> JAVI · JOSE LUIS | H6: =IF('CALENDARIO 2026'!K18="G",1,0) -> 1 | I6: =IF('CALENDARIO 2026'!K19="G",1,0) -> 0 | J6: =IF('CALENDARIO 2026'!K20="G",1,0) -> 1 | K6: =IF('CALENDARIO 2026'!K21="G",1,0) -> 0 | L6: =IF('CALENDARIO 2026'!K22="G",1,0) -> 0
B7: 5 | C7: 46342 | D7: 46348 | E7: =LEFT(IF('CALENDARIO 2026'!R18="G","JAVI · ","")&IF('CALENDARIO 2026'!R19="G","JOSE · ","")&IF('CALENDARIO 2026'!R20="G","JOSE LUIS · ","")&IF('CALENDARIO 2026'!R21="G","ALBERTO · ","")&IF('CALENDARIO 2026'!R22="G","MOLINERO · ",""),LEN(IF('CALENDARIO 2026'!R18="G","JAVI · ","")&IF('CALENDARIO 2026'!R19="G","JOSE · ","")&IF('CALENDARIO 2026'!R20="G","JOSE LUIS · ","")&IF('CALENDARIO 2026'!R21="G","ALBERTO · ","")&IF('CALENDARIO 2026'!R22="G","MOLINERO · ",""))-3) -> JOSE · MOLINERO | H7: =IF('CALENDARIO 2026'!R18="G",1,0) -> 0 | I7: =IF('CALENDARIO 2026'!R19="G",1,0) -> 1 | J7: =IF('CALENDARIO 2026'!R20="G",1,0) -> 0 | K7: =IF('CALENDARIO 2026'!R21="G",1,0) -> 0 | L7: =IF('CALENDARIO 2026'!R22="G",1,0) -> 1
B8: 6 | C8: 46349 | D8: 46355 | E8: =LEFT(IF('CALENDARIO 2026'!Y18="G","JAVI · ","")&IF('CALENDARIO 2026'!Y19="G","JOSE · ","")&IF('CALENDARIO 2026'!Y20="G","JOSE LUIS · ","")&IF('CALENDARIO 2026'!Y21="G","ALBERTO · ","")&IF('CALENDARIO 2026'!Y22="G","MOLINERO · ",""),LEN(IF('CALENDARIO 2026'!Y18="G","JAVI · ","")&IF('CALENDARIO 2026'!Y19="G","JOSE · ","")&IF('CALENDARIO 2026'!Y20="G","JOSE LUIS · ","")&IF('CALENDARIO 2026'!Y21="G","ALBERTO · ","")&IF('CALENDARIO 2026'!Y22="G","MOLINERO · ",""))-3) -> JAVI · ALBERTO | H8: =IF('CALENDARIO 2026'!Y18="G",1,0) -> 1 | I8: =IF('CALENDARIO 2026'!Y19="G",1,0) -> 0 | J8: =IF('CALENDARIO 2026'!Y20="G",1,0) -> 0 | K8: =IF('CALENDARIO 2026'!Y21="G",1,0) -> 1 | L8: =IF('CALENDARIO 2026'!Y22="G",1,0) -> 0
B9: 7 | C9: 46356 | D9: 46362 | E9: =LEFT(IF('CALENDARIO 2026'!AF18="G","JAVI · ","")&IF('CALENDARIO 2026'!AF19="G","JOSE · ","")&IF('CALENDARIO 2026'!AF20="G","JOSE LUIS · ","")&IF('CALENDARIO 2026'!AF21="G","ALBERTO · ","")&IF('CALENDARIO 2026'!AF22="G","MOLINERO · ",""),LEN(IF('CALENDARIO 2026'!AF18="G","JAVI · ","")&IF('CALENDARIO 2026'!AF19="G","JOSE · ","")&IF('CALENDARIO 2026'!AF20="G","JOSE LUIS · ","")&IF('CALENDARIO 2026'!AF21="G","ALBERTO · ","")&IF('CALENDARIO 2026'!AF22="G","MOLINERO · ",""))-3) -> JOSE · JOSE LUIS | H9: =IF('CALENDARIO 2026'!AF18="G",1,0) -> 0 | I9: =IF('CALENDARIO 2026'!AF19="G",1,0) -> 1 | J9: =IF('CALENDARIO 2026'!AF20="G",1,0) -> 1 | K9: =IF('CALENDARIO 2026'!AF21="G",1,0) -> 0 | L9: =IF('CALENDARIO 2026'!AF22="G",1,0) -> 0
B10: 8 | C10: 46363 | D10: 46369 | E10: =LEFT(IF('CALENDARIO 2026'!I27="G","JAVI · ","")&IF('CALENDARIO 2026'!I28="G","JOSE · ","")&IF('CALENDARIO 2026'!I29="G","JOSE LUIS · ","")&IF('CALENDARIO 2026'!I30="G","ALBERTO · ","")&IF('CALENDARIO 2026'!I31="G","MOLINERO · ",""),LEN(IF('CALENDARIO 2026'!I27="G","JAVI · ","")&IF('CALENDARIO 2026'!I28="G","JOSE · ","")&IF('CALENDARIO 2026'!I29="G","JOSE LUIS · ","")&IF('CALENDARIO 2026'!I30="G","ALBERTO · ","")&IF('CALENDARIO 2026'!I31="G","MOLINERO · ",""))-3) -> ALBERTO · MOLINERO | F10: 7/12 Día de la Constitución (trasladado del dom. 6) | 8/12 Inmaculada Concepción | H10: =IF('CALENDARIO 2026'!I27="G",1,0) -> 0 | I10: =IF('CALENDARIO 2026'!I28="G",1,0) -> 0 | J10: =IF('CALENDARIO 2026'!I29="G",1,0) -> 0 | K10: =IF('CALENDARIO 2026'!I30="G",1,0) -> 1 | L10: =IF('CALENDARIO 2026'!I31="G",1,0) -> 1
B11: 9 | C11: 46370 | D11: 46376 | E11: =LEFT(IF('CALENDARIO 2026'!P27="G","JAVI · ","")&IF('CALENDARIO 2026'!P28="G","JOSE · ","")&IF('CALENDARIO 2026'!P29="G","JOSE LUIS · ","")&IF('CALENDARIO 2026'!P30="G","ALBERTO · ","")&IF('CALENDARIO 2026'!P31="G","MOLINERO · ",""),LEN(IF('CALENDARIO 2026'!P27="G","JAVI · ","")&IF('CALENDARIO 2026'!P28="G","JOSE · ","")&IF('CALENDARIO 2026'!P29="G","JOSE LUIS · ","")&IF('CALENDARIO 2026'!P30="G","ALBERTO · ","")&IF('CALENDARIO 2026'!P31="G","MOLINERO · ",""))-3) -> JAVI · JOSE LUIS | H11: =IF('CALENDARIO 2026'!P27="G",1,0) -> 1 | I11: =IF('CALENDARIO 2026'!P28="G",1,0) -> 0 | J11: =IF('CALENDARIO 2026'!P29="G",1,0) -> 1 | K11: =IF('CALENDARIO 2026'!P30="G",1,0) -> 0 | L11: =IF('CALENDARIO 2026'!P31="G",1,0) -> 0
B12: 10 | C12: 46377 | D12: 46383 | E12: =LEFT(IF('CALENDARIO 2026'!W27="G","JAVI · ","")&IF('CALENDARIO 2026'!W28="G","JOSE · ","")&IF('CALENDARIO 2026'!W29="G","JOSE LUIS · ","")&IF('CALENDARIO 2026'!W30="G","ALBERTO · ","")&IF('CALENDARIO 2026'!W31="G","MOLINERO · ",""),LEN(IF('CALENDARIO 2026'!W27="G","JAVI · ","")&IF('CALENDARIO 2026'!W28="G","JOSE · ","")&IF('CALENDARIO 2026'!W29="G","JOSE LUIS · ","")&IF('CALENDARIO 2026'!W30="G","ALBERTO · ","")&IF('CALENDARIO 2026'!W31="G","MOLINERO · ",""))-3) -> JOSE · MOLINERO | F12: 24/12 Nochebuena | 25/12 Natividad del Señor (Navidad) | H12: =IF('CALENDARIO 2026'!W27="G",1,0) -> 0 | I12: =IF('CALENDARIO 2026'!W28="G",1,0) -> 1 | J12: =IF('CALENDARIO 2026'!W29="G",1,0) -> 0 | K12: =IF('CALENDARIO 2026'!W30="G",1,0) -> 0 | L12: =IF('CALENDARIO 2026'!W31="G",1,0) -> 1
B13: 11 | C13: 46384 | D13: 46390 | E13: =LEFT(IF('CALENDARIO 2026'!AD27="G","JAVI · ","")&IF('CALENDARIO 2026'!AD28="G","JOSE · ","")&IF('CALENDARIO 2026'!AD29="G","JOSE LUIS · ","")&IF('CALENDARIO 2026'!AD30="G","ALBERTO · ","")&IF('CALENDARIO 2026'!AD31="G","MOLINERO · ",""),LEN(IF('CALENDARIO 2026'!AD27="G","JAVI · ","")&IF('CALENDARIO 2026'!AD28="G","JOSE · ","")&IF('CALENDARIO 2026'!AD29="G","JOSE LUIS · ","")&IF('CALENDARIO 2026'!AD30="G","ALBERTO · ","")&IF('CALENDARIO 2026'!AD31="G","MOLINERO · ",""))-3) -> JAVI · JOSE LUIS | F13: 31/12 Nochevieja | 1/1 Año Nuevo | H13: =IF('CALENDARIO 2026'!AD27="G",1,0) -> 1 | I13: =IF('CALENDARIO 2026'!AD28="G",1,0) -> 0 | J13: =IF('CALENDARIO 2026'!AD29="G",1,0) -> 1 | K13: =IF('CALENDARIO 2026'!AD30="G",1,0) -> 0 | L13: =IF('CALENDARIO 2026'!AD31="G",1,0) -> 0
B14: 12 | C14: 46391 | D14: 46397 | E14: =LEFT(IF('CALENDARIO 2027'!F8="G","JAVI · ","")&IF('CALENDARIO 2027'!F9="G","JOSE · ","")&IF('CALENDARIO 2027'!F10="G","JOSE LUIS · ","")&IF('CALENDARIO 2027'!F11="G","ALBERTO · ","")&IF('CALENDARIO 2027'!F12="G","MOLINERO · ",""),LEN(IF('CALENDARIO 2027'!F8="G","JAVI · ","")&IF('CALENDARIO 2027'!F9="G","JOSE · ","")&IF('CALENDARIO 2027'!F10="G","JOSE LUIS · ","")&IF('CALENDARIO 2027'!F11="G","ALBERTO · ","")&IF('CALENDARIO 2027'!F12="G","MOLINERO · ",""))-3) -> JOSE · ALBERTO | F14: 6/1 Epifanía del Señor (Reyes) | H14: =IF('CALENDARIO 2027'!F8="G",1,0) -> 0 | I14: =IF('CALENDARIO 2027'!F9="G",1,0) -> 1 | J14: =IF('CALENDARIO 2027'!F10="G",1,0) -> 0 | K14: =IF('CALENDARIO 2027'!F11="G",1,0) -> 1 | L14: =IF('CALENDARIO 2027'!F12="G",1,0) -> 0
B15: 13 | C15: 46398 | D15: 46404 | E15: =LEFT(IF('CALENDARIO 2027'!M8="G","JAVI · ","")&IF('CALENDARIO 2027'!M9="G","JOSE · ","")&IF('CALENDARIO 2027'!M10="G","JOSE LUIS · ","")&IF('CALENDARIO 2027'!M11="G","ALBERTO · ","")&IF('CALENDARIO 2027'!M12="G","MOLINERO · ",""),LEN(IF('CALENDARIO 2027'!M8="G","JAVI · ","")&IF('CALENDARIO 2027'!M9="G","JOSE · ","")&IF('CALENDARIO 2027'!M10="G","JOSE LUIS · ","")&IF('CALENDARIO 2027'!M11="G","ALBERTO · ","")&IF('CALENDARIO 2027'!M12="G","MOLINERO · ",""))-3) -> JAVI · MOLINERO | H15: =IF('CALENDARIO 2027'!M8="G",1,0) -> 1 | I15: =IF('CALENDARIO 2027'!M9="G",1,0) -> 0 | J15: =IF('CALENDARIO 2027'!M10="G",1,0) -> 0 | K15: =IF('CALENDARIO 2027'!M11="G",1,0) -> 0 | L15: =IF('CALENDARIO 2027'!M12="G",1,0) -> 1
B16: 14 | C16: 46405 | D16: 46411 | E16: =LEFT(IF('CALENDARIO 2027'!T8="G","JAVI · ","")&IF('CALENDARIO 2027'!T9="G","JOSE · ","")&IF('CALENDARIO 2027'!T10="G","JOSE LUIS · ","")&IF('CALENDARIO 2027'!T11="G","ALBERTO · ","")&IF('CALENDARIO 2027'!T12="G","MOLINERO · ",""),LEN(IF('CALENDARIO 2027'!T8="G","JAVI · ","")&IF('CALENDARIO 2027'!T9="G","JOSE · ","")&IF('CALENDARIO 2027'!T10="G","JOSE LUIS · ","")&IF('CALENDARIO 2027'!T11="G","ALBERTO · ","")&IF('CALENDARIO 2027'!T12="G","MOLINERO · ",""))-3) -> JOSE LUIS · ALBERTO | H16: =IF('CALENDARIO 2027'!T8="G",1,0) -> 0 | I16: =IF('CALENDARIO 2027'!T9="G",1,0) -> 0 | J16: =IF('CALENDARIO 2027'!T10="G",1,0) -> 1 | K16: =IF('CALENDARIO 2027'!T11="G",1,0) -> 1 | L16: =IF('CALENDARIO 2027'!T12="G",1,0) -> 0
B17: 15 | C17: 46412 | D17: 46418 | E17: =LEFT(IF('CALENDARIO 2027'!AA8="G","JAVI · ","")&IF('CALENDARIO 2027'!AA9="G","JOSE · ","")&IF('CALENDARIO 2027'!AA10="G","JOSE LUIS · ","")&IF('CALENDARIO 2027'!AA11="G","ALBERTO · ","")&IF('CALENDARIO 2027'!AA12="G","MOLINERO · ",""),LEN(IF('CALENDARIO 2027'!AA8="G","JAVI · ","")&IF('CALENDARIO 2027'!AA9="G","JOSE · ","")&IF('CALENDARIO 2027'!AA10="G","JOSE LUIS · ","")&IF('CALENDARIO 2027'!AA11="G","ALBERTO · ","")&IF('CALENDARIO 2027'!AA12="G","MOLINERO · ",""))-3) -> JOSE · MOLINERO | H17: =IF('CALENDARIO 2027'!AA8="G",1,0) -> 0 | I17: =IF('CALENDARIO 2027'!AA9="G",1,0) -> 1 | J17: =IF('CALENDARIO 2027'!AA10="G",1,0) -> 0 | K17: =IF('CALENDARIO 2027'!AA11="G",1,0) -> 0 | L17: =IF('CALENDARIO 2027'!AA12="G",1,0) -> 1
B18: 16 | C18: 46419 | D18: 46425 | E18: =LEFT(IF('CALENDARIO 2027'!C17="G","JAVI · ","")&IF('CALENDARIO 2027'!C18="G","JOSE · ","")&IF('CALENDARIO 2027'!C19="G","JOSE LUIS · ","")&IF('CALENDARIO 2027'!C20="G","ALBERTO · ","")&IF('CALENDARIO 2027'!C21="G","MOLINERO · ",""),LEN(IF('CALENDARIO 2027'!C17="G","JAVI · ","")&IF('CALENDARIO 2027'!C18="G","JOSE · ","")&IF('CALENDARIO 2027'!C19="G","JOSE LUIS · ","")&IF('CALENDARIO 2027'!C20="G","ALBERTO · ","")&IF('CALENDARIO 2027'!C21="G","MOLINERO · ",""))-3) -> JAVI · ALBERTO | H18: =IF('CALENDARIO 2027'!C17="G",1,0) -> 1 | I18: =IF('CALENDARIO 2027'!C18="G",1,0) -> 0 | J18: =IF('CALENDARIO 2027'!C19="G",1,0) -> 0 | K18: =IF('CALENDARIO 2027'!C20="G",1,0) -> 1 | L18: =IF('CALENDARIO 2027'!C21="G",1,0) -> 0
B19: 17 | C19: 46426 | D19: 46432 | E19: =LEFT(IF('CALENDARIO 2027'!J17="G","JAVI · ","")&IF('CALENDARIO 2027'!J18="G","JOSE · ","")&IF('CALENDARIO 2027'!J19="G","JOSE LUIS · ","")&IF('CALENDARIO 2027'!J20="G","ALBERTO · ","")&IF('CALENDARIO 2027'!J21="G","MOLINERO · ",""),LEN(IF('CALENDARIO 2027'!J17="G","JAVI · ","")&IF('CALENDARIO 2027'!J18="G","JOSE · ","")&IF('CALENDARIO 2027'!J19="G","JOSE LUIS · ","")&IF('CALENDARIO 2027'!J20="G","ALBERTO · ","")&IF('CALENDARIO 2027'!J21="G","MOLINERO · ",""))-3) -> JOSE · JOSE LUIS | H19: =IF('CALENDARIO 2027'!J17="G",1,0) -> 0 | I19: =IF('CALENDARIO 2027'!J18="G",1,0) -> 1 | J19: =IF('CALENDARIO 2027'!J19="G",1,0) -> 1 | K19: =IF('CALENDARIO 2027'!J20="G",1,0) -> 0 | L19: =IF('CALENDARIO 2027'!J21="G",1,0) -> 0
B20: 18 | C20: 46433 | D20: 46439 | E20: =LEFT(IF('CALENDARIO 2027'!Q17="G","JAVI · ","")&IF('CALENDARIO 2027'!Q18="G","JOSE · ","")&IF('CALENDARIO 2027'!Q19="G","JOSE LUIS · ","")&IF('CALENDARIO 2027'!Q20="G","ALBERTO · ","")&IF('CALENDARIO 2027'!Q21="G","MOLINERO · ",""),LEN(IF('CALENDARIO 2027'!Q17="G","JAVI · ","")&IF('CALENDARIO 2027'!Q18="G","JOSE · ","")&IF('CALENDARIO 2027'!Q19="G","JOSE LUIS · ","")&IF('CALENDARIO 2027'!Q20="G","ALBERTO · ","")&IF('CALENDARIO 2027'!Q21="G","MOLINERO · ",""))-3) -> JAVI · MOLINERO | H20: =IF('CALENDARIO 2027'!Q17="G",1,0) -> 1 | I20: =IF('CALENDARIO 2027'!Q18="G",1,0) -> 0 | J20: =IF('CALENDARIO 2027'!Q19="G",1,0) -> 0 | K20: =IF('CALENDARIO 2027'!Q20="G",1,0) -> 0 | L20: =IF('CALENDARIO 2027'!Q21="G",1,0) -> 1
B21: 19 | C21: 46440 | D21: 46446 | E21: =LEFT(IF('CALENDARIO 2027'!X17="G","JAVI · ","")&IF('CALENDARIO 2027'!X18="G","JOSE · ","")&IF('CALENDARIO 2027'!X19="G","JOSE LUIS · ","")&IF('CALENDARIO 2027'!X20="G","ALBERTO · ","")&IF('CALENDARIO 2027'!X21="G","MOLINERO · ",""),LEN(IF('CALENDARIO 2027'!X17="G","JAVI · ","")&IF('CALENDARIO 2027'!X18="G","JOSE · ","")&IF('CALENDARIO 2027'!X19="G","JOSE LUIS · ","")&IF('CALENDARIO 2027'!X20="G","ALBERTO · ","")&IF('CALENDARIO 2027'!X21="G","MOLINERO · ",""))-3) -> JOSE LUIS · ALBERTO | H21: =IF('CALENDARIO 2027'!X17="G",1,0) -> 0 | I21: =IF('CALENDARIO 2027'!X18="G",1,0) -> 0 | J21: =IF('CALENDARIO 2027'!X19="G",1,0) -> 1 | K21: =IF('CALENDARIO 2027'!X20="G",1,0) -> 1 | L21: =IF('CALENDARIO 2027'!X21="G",1,0) -> 0
B22: 20 | C22: 46447 | D22: 46453 | E22: =LEFT(IF('CALENDARIO 2027'!C26="G","JAVI · ","")&IF('CALENDARIO 2027'!C27="G","JOSE · ","")&IF('CALENDARIO 2027'!C28="G","JOSE LUIS · ","")&IF('CALENDARIO 2027'!C29="G","ALBERTO · ","")&IF('CALENDARIO 2027'!C30="G","MOLINERO · ",""),LEN(IF('CALENDARIO 2027'!C26="G","JAVI · ","")&IF('CALENDARIO 2027'!C27="G","JOSE · ","")&IF('CALENDARIO 2027'!C28="G","JOSE LUIS · ","")&IF('CALENDARIO 2027'!C29="G","ALBERTO · ","")&IF('CALENDARIO 2027'!C30="G","MOLINERO · ",""))-3) -> JAVI · JOSE | F22: 1/3 Día de Andalucía (trasladado del dom. 28/02) | H22: =IF('CALENDARIO 2027'!C26="G",1,0) -> 1 | I22: =IF('CALENDARIO 2027'!C27="G",1,0) -> 1 | J22: =IF('CALENDARIO 2027'!C28="G",1,0) -> 0 | K22: =IF('CALENDARIO 2027'!C29="G",1,0) -> 0 | L22: =IF('CALENDARIO 2027'!C30="G",1,0) -> 0
B23: 21 | C23: 46454 | D23: 46460 | E23: =LEFT(IF('CALENDARIO 2027'!J26="G","JAVI · ","")&IF('CALENDARIO 2027'!J27="G","JOSE · ","")&IF('CALENDARIO 2027'!J28="G","JOSE LUIS · ","")&IF('CALENDARIO 2027'!J29="G","ALBERTO · ","")&IF('CALENDARIO 2027'!J30="G","MOLINERO · ",""),LEN(IF('CALENDARIO 2027'!J26="G","JAVI · ","")&IF('CALENDARIO 2027'!J27="G","JOSE · ","")&IF('CALENDARIO 2027'!J28="G","JOSE LUIS · ","")&IF('CALENDARIO 2027'!J29="G","ALBERTO · ","")&IF('CALENDARIO 2027'!J30="G","MOLINERO · ",""))-3) -> JOSE LUIS · MOLINERO | H23: =IF('CALENDARIO 2027'!J26="G",1,0) -> 0 | I23: =IF('CALENDARIO 2027'!J27="G",1,0) -> 0 | J23: =IF('CALENDARIO 2027'!J28="G",1,0) -> 1 | K23: =IF('CALENDARIO 2027'!J29="G",1,0) -> 0 | L23: =IF('CALENDARIO 2027'!J30="G",1,0) -> 1
B24: 22 | C24: 46461 | D24: 46467 | E24: =LEFT(IF('CALENDARIO 2027'!Q26="G","JAVI · ","")&IF('CALENDARIO 2027'!Q27="G","JOSE · ","")&IF('CALENDARIO 2027'!Q28="G","JOSE LUIS · ","")&IF('CALENDARIO 2027'!Q29="G","ALBERTO · ","")&IF('CALENDARIO 2027'!Q30="G","MOLINERO · ",""),LEN(IF('CALENDARIO 2027'!Q26="G","JAVI · ","")&IF('CALENDARIO 2027'!Q27="G","JOSE · ","")&IF('CALENDARIO 2027'!Q28="G","JOSE LUIS · ","")&IF('CALENDARIO 2027'!Q29="G","ALBERTO · ","")&IF('CALENDARIO 2027'!Q30="G","MOLINERO · ",""))-3) -> JOSE · ALBERTO | H24: =IF('CALENDARIO 2027'!Q26="G",1,0) -> 0 | I24: =IF('CALENDARIO 2027'!Q27="G",1,0) -> 1 | J24: =IF('CALENDARIO 2027'!Q28="G",1,0) -> 0 | K24: =IF('CALENDARIO 2027'!Q29="G",1,0) -> 1 | L24: =IF('CALENDARIO 2027'!Q30="G",1,0) -> 0
B25: 23 | C25: 46468 | D25: 46474 | E25: =LEFT(IF('CALENDARIO 2027'!X26="G","JAVI · ","")&IF('CALENDARIO 2027'!X27="G","JOSE · ","")&IF('CALENDARIO 2027'!X28="G","JOSE LUIS · ","")&IF('CALENDARIO 2027'!X29="G","ALBERTO · ","")&IF('CALENDARIO 2027'!X30="G","MOLINERO · ",""),LEN(IF('CALENDARIO 2027'!X26="G","JAVI · ","")&IF('CALENDARIO 2027'!X27="G","JOSE · ","")&IF('CALENDARIO 2027'!X28="G","JOSE LUIS · ","")&IF('CALENDARIO 2027'!X29="G","ALBERTO · ","")&IF('CALENDARIO 2027'!X30="G","MOLINERO · ",""))-3) -> JAVI · MOLINERO | F25: 25/3 Jueves Santo | 26/3 Viernes Santo | H25: =IF('CALENDARIO 2027'!X26="G",1,0) -> 1 | I25: =IF('CALENDARIO 2027'!X27="G",1,0) -> 0 | J25: =IF('CALENDARIO 2027'!X28="G",1,0) -> 0 | K25: =IF('CALENDARIO 2027'!X29="G",1,0) -> 0 | L25: =IF('CALENDARIO 2027'!X30="G",1,0) -> 1
B26: 24 | C26: 46475 | D26: 46481 | E26: =LEFT(IF('CALENDARIO 2027'!AE26="G","JAVI · ","")&IF('CALENDARIO 2027'!AE27="G","JOSE · ","")&IF('CALENDARIO 2027'!AE28="G","JOSE LUIS · ","")&IF('CALENDARIO 2027'!AE29="G","ALBERTO · ","")&IF('CALENDARIO 2027'!AE30="G","MOLINERO · ",""),LEN(IF('CALENDARIO 2027'!AE26="G","JAVI · ","")&IF('CALENDARIO 2027'!AE27="G","JOSE · ","")&IF('CALENDARIO 2027'!AE28="G","JOSE LUIS · ","")&IF('CALENDARIO 2027'!AE29="G","ALBERTO · ","")&IF('CALENDARIO 2027'!AE30="G","MOLINERO · ",""))-3) -> JOSE · JOSE LUIS | H26: =IF('CALENDARIO 2027'!AE26="G",1,0) -> 0 | I26: =IF('CALENDARIO 2027'!AE27="G",1,0) -> 1 | J26: =IF('CALENDARIO 2027'!AE28="G",1,0) -> 1 | K26: =IF('CALENDARIO 2027'!AE29="G",1,0) -> 0 | L26: =IF('CALENDARIO 2027'!AE30="G",1,0) -> 0
B27: 25 | C27: 46482 | D27: 46488 | E27: =LEFT(IF('CALENDARIO 2027'!G35="G","JAVI · ","")&IF('CALENDARIO 2027'!G36="G","JOSE · ","")&IF('CALENDARIO 2027'!G37="G","JOSE LUIS · ","")&IF('CALENDARIO 2027'!G38="G","ALBERTO · ","")&IF('CALENDARIO 2027'!G39="G","MOLINERO · ",""),LEN(IF('CALENDARIO 2027'!G35="G","JAVI · ","")&IF('CALENDARIO 2027'!G36="G","JOSE · ","")&IF('CALENDARIO 2027'!G37="G","JOSE LUIS · ","")&IF('CALENDARIO 2027'!G38="G","ALBERTO · ","")&IF('CALENDARIO 2027'!G39="G","MOLINERO · ",""))-3) -> ALBERTO · MOLINERO | H27: =IF('CALENDARIO 2027'!G35="G",1,0) -> 0 | I27: =IF('CALENDARIO 2027'!G36="G",1,0) -> 0 | J27: =IF('CALENDARIO 2027'!G37="G",1,0) -> 0 | K27: =IF('CALENDARIO 2027'!G38="G",1,0) -> 1 | L27: =IF('CALENDARIO 2027'!G39="G",1,0) -> 1
B28: 26 | C28: 46489 | D28: 46495 | E28: =LEFT(IF('CALENDARIO 2027'!N35="G","JAVI · ","")&IF('CALENDARIO 2027'!N36="G","JOSE · ","")&IF('CALENDARIO 2027'!N37="G","JOSE LUIS · ","")&IF('CALENDARIO 2027'!N38="G","ALBERTO · ","")&IF('CALENDARIO 2027'!N39="G","MOLINERO · ",""),LEN(IF('CALENDARIO 2027'!N35="G","JAVI · ","")&IF('CALENDARIO 2027'!N36="G","JOSE · ","")&IF('CALENDARIO 2027'!N37="G","JOSE LUIS · ","")&IF('CALENDARIO 2027'!N38="G","ALBERTO · ","")&IF('CALENDARIO 2027'!N39="G","MOLINERO · ",""))-3) -> JAVI · JOSE LUIS | F28: 14/4 Miércoles de Feria | H28: =IF('CALENDARIO 2027'!N35="G",1,0) -> 1 | I28: =IF('CALENDARIO 2027'!N36="G",1,0) -> 0 | J28: =IF('CALENDARIO 2027'!N37="G",1,0) -> 1 | K28: =IF('CALENDARIO 2027'!N38="G",1,0) -> 0 | L28: =IF('CALENDARIO 2027'!N39="G",1,0) -> 0
B29: 27 | C29: 46496 | D29: 46502 | E29: =LEFT(IF('CALENDARIO 2027'!U35="G","JAVI · ","")&IF('CALENDARIO 2027'!U36="G","JOSE · ","")&IF('CALENDARIO 2027'!U37="G","JOSE LUIS · ","")&IF('CALENDARIO 2027'!U38="G","ALBERTO · ","")&IF('CALENDARIO 2027'!U39="G","MOLINERO · ",""),LEN(IF('CALENDARIO 2027'!U35="G","JAVI · ","")&IF('CALENDARIO 2027'!U36="G","JOSE · ","")&IF('CALENDARIO 2027'!U37="G","JOSE LUIS · ","")&IF('CALENDARIO 2027'!U38="G","ALBERTO · ","")&IF('CALENDARIO 2027'!U39="G","MOLINERO · ",""))-3) -> JOSE · ALBERTO | H29: =IF('CALENDARIO 2027'!U35="G",1,0) -> 0 | I29: =IF('CALENDARIO 2027'!U36="G",1,0) -> 1 | J29: =IF('CALENDARIO 2027'!U37="G",1,0) -> 0 | K29: =IF('CALENDARIO 2027'!U38="G",1,0) -> 1 | L29: =IF('CALENDARIO 2027'!U39="G",1,0) -> 0
B30: 28 | C30: 46503 | D30: 46509 | E30: =LEFT(IF('CALENDARIO 2027'!AB35="G","JAVI · ","")&IF('CALENDARIO 2027'!AB36="G","JOSE · ","")&IF('CALENDARIO 2027'!AB37="G","JOSE LUIS · ","")&IF('CALENDARIO 2027'!AB38="G","ALBERTO · ","")&IF('CALENDARIO 2027'!AB39="G","MOLINERO · ",""),LEN(IF('CALENDARIO 2027'!AB35="G","JAVI · ","")&IF('CALENDARIO 2027'!AB36="G","JOSE · ","")&IF('CALENDARIO 2027'!AB37="G","JOSE LUIS · ","")&IF('CALENDARIO 2027'!AB38="G","ALBERTO · ","")&IF('CALENDARIO 2027'!AB39="G","MOLINERO · ",""))-3) -> JOSE LUIS · MOLINERO | F30: 1/5 Fiesta del Trabajo | H30: =IF('CALENDARIO 2027'!AB35="G",1,0) -> 0 | I30: =IF('CALENDARIO 2027'!AB36="G",1,0) -> 0 | J30: =IF('CALENDARIO 2027'!AB37="G",1,0) -> 1 | K30: =IF('CALENDARIO 2027'!AB38="G",1,0) -> 0 | L30: =IF('CALENDARIO 2027'!AB39="G",1,0) -> 1
B31: 29 | C31: 46510 | D31: 46516 | E31: =LEFT(IF('CALENDARIO 2027'!E44="G","JAVI · ","")&IF('CALENDARIO 2027'!E45="G","JOSE · ","")&IF('CALENDARIO 2027'!E46="G","JOSE LUIS · ","")&IF('CALENDARIO 2027'!E47="G","ALBERTO · ","")&IF('CALENDARIO 2027'!E48="G","MOLINERO · ",""),LEN(IF('CALENDARIO 2027'!E44="G","JAVI · ","")&IF('CALENDARIO 2027'!E45="G","JOSE · ","")&IF('CALENDARIO 2027'!E46="G","JOSE LUIS · ","")&IF('CALENDARIO 2027'!E47="G","ALBERTO · ","")&IF('CALENDARIO 2027'!E48="G","MOLINERO · ",""))-3) -> JAVI · ALBERTO | H31: =IF('CALENDARIO 2027'!E44="G",1,0) -> 1 | I31: =IF('CALENDARIO 2027'!E45="G",1,0) -> 0 | J31: =IF('CALENDARIO 2027'!E46="G",1,0) -> 0 | K31: =IF('CALENDARIO 2027'!E47="G",1,0) -> 1 | L31: =IF('CALENDARIO 2027'!E48="G",1,0) -> 0
B32: 30 | C32: 46517 | D32: 46523 | E32: =LEFT(IF('CALENDARIO 2027'!L44="G","JAVI · ","")&IF('CALENDARIO 2027'!L45="G","JOSE · ","")&IF('CALENDARIO 2027'!L46="G","JOSE LUIS · ","")&IF('CALENDARIO 2027'!L47="G","ALBERTO · ","")&IF('CALENDARIO 2027'!L48="G","MOLINERO · ",""),LEN(IF('CALENDARIO 2027'!L44="G","JAVI · ","")&IF('CALENDARIO 2027'!L45="G","JOSE · ","")&IF('CALENDARIO 2027'!L46="G","JOSE LUIS · ","")&IF('CALENDARIO 2027'!L47="G","ALBERTO · ","")&IF('CALENDARIO 2027'!L48="G","MOLINERO · ",""))-3) -> JOSE · MOLINERO | H32: =IF('CALENDARIO 2027'!L44="G",1,0) -> 0 | I32: =IF('CALENDARIO 2027'!L45="G",1,0) -> 1 | J32: =IF('CALENDARIO 2027'!L46="G",1,0) -> 0 | K32: =IF('CALENDARIO 2027'!L47="G",1,0) -> 0 | L32: =IF('CALENDARIO 2027'!L48="G",1,0) -> 1
B33: 31 | C33: 46524 | D33: 46530 | E33: =LEFT(IF('CALENDARIO 2027'!S44="G","JAVI · ","")&IF('CALENDARIO 2027'!S45="G","JOSE · ","")&IF('CALENDARIO 2027'!S46="G","JOSE LUIS · ","")&IF('CALENDARIO 2027'!S47="G","ALBERTO · ","")&IF('CALENDARIO 2027'!S48="G","MOLINERO · ",""),LEN(IF('CALENDARIO 2027'!S44="G","JAVI · ","")&IF('CALENDARIO 2027'!S45="G","JOSE · ","")&IF('CALENDARIO 2027'!S46="G","JOSE LUIS · ","")&IF('CALENDARIO 2027'!S47="G","ALBERTO · ","")&IF('CALENDARIO 2027'!S48="G","MOLINERO · ",""))-3) -> JAVI · JOSE LUIS | H33: =IF('CALENDARIO 2027'!S44="G",1,0) -> 1 | I33: =IF('CALENDARIO 2027'!S45="G",1,0) -> 0 | J33: =IF('CALENDARIO 2027'!S46="G",1,0) -> 1 | K33: =IF('CALENDARIO 2027'!S47="G",1,0) -> 0 | L33: =IF('CALENDARIO 2027'!S48="G",1,0) -> 0
B34: 32 | C34: 46531 | D34: 46537 | E34: =LEFT(IF('CALENDARIO 2027'!Z44="G","JAVI · ","")&IF('CALENDARIO 2027'!Z45="G","JOSE · ","")&IF('CALENDARIO 2027'!Z46="G","JOSE LUIS · ","")&IF('CALENDARIO 2027'!Z47="G","ALBERTO · ","")&IF('CALENDARIO 2027'!Z48="G","MOLINERO · ",""),LEN(IF('CALENDARIO 2027'!Z44="G","JAVI · ","")&IF('CALENDARIO 2027'!Z45="G","JOSE · ","")&IF('CALENDARIO 2027'!Z46="G","JOSE LUIS · ","")&IF('CALENDARIO 2027'!Z47="G","ALBERTO · ","")&IF('CALENDARIO 2027'!Z48="G","MOLINERO · ",""))-3) -> JOSE · ALBERTO | F34: 27/5 Corpus Christi | H34: =IF('CALENDARIO 2027'!Z44="G",1,0) -> 0 | I34: =IF('CALENDARIO 2027'!Z45="G",1,0) -> 1 | J34: =IF('CALENDARIO 2027'!Z46="G",1,0) -> 0 | K34: =IF('CALENDARIO 2027'!Z47="G",1,0) -> 1 | L34: =IF('CALENDARIO 2027'!Z48="G",1,0) -> 0
B35: 33 | C35: 46538 | D35: 46544 | E35: =LEFT(IF('CALENDARIO 2027'!AG44="G","JAVI · ","")&IF('CALENDARIO 2027'!AG45="G","JOSE · ","")&IF('CALENDARIO 2027'!AG46="G","JOSE LUIS · ","")&IF('CALENDARIO 2027'!AG47="G","ALBERTO · ","")&IF('CALENDARIO 2027'!AG48="G","MOLINERO · ",""),LEN(IF('CALENDARIO 2027'!AG44="G","JAVI · ","")&IF('CALENDARIO 2027'!AG45="G","JOSE · ","")&IF('CALENDARIO 2027'!AG46="G","JOSE LUIS · ","")&IF('CALENDARIO 2027'!AG47="G","ALBERTO · ","")&IF('CALENDARIO 2027'!AG48="G","MOLINERO · ",""))-3) -> JOSE LUIS · MOLINERO | H35: =IF('CALENDARIO 2027'!AG44="G",1,0) -> 0 | I35: =IF('CALENDARIO 2027'!AG45="G",1,0) -> 0 | J35: =IF('CALENDARIO 2027'!AG46="G",1,0) -> 1 | K35: =IF('CALENDARIO 2027'!AG47="G",1,0) -> 0 | L35: =IF('CALENDARIO 2027'!AG48="G",1,0) -> 1
B36: 34 | C36: 46545 | D36: 46551 | E36: =LEFT(IF('CALENDARIO 2027'!I53="G","JAVI · ","")&IF('CALENDARIO 2027'!I54="G","JOSE · ","")&IF('CALENDARIO 2027'!I55="G","JOSE LUIS · ","")&IF('CALENDARIO 2027'!I56="G","ALBERTO · ","")&IF('CALENDARIO 2027'!I57="G","MOLINERO · ",""),LEN(IF('CALENDARIO 2027'!I53="G","JAVI · ","")&IF('CALENDARIO 2027'!I54="G","JOSE · ","")&IF('CALENDARIO 2027'!I55="G","JOSE LUIS · ","")&IF('CALENDARIO 2027'!I56="G","ALBERTO · ","")&IF('CALENDARIO 2027'!I57="G","MOLINERO · ",""))-3) -> JAVI · ALBERTO | H36: =IF('CALENDARIO 2027'!I53="G",1,0) -> 1 | I36: =IF('CALENDARIO 2027'!I54="G",1,0) -> 0 | J36: =IF('CALENDARIO 2027'!I55="G",1,0) -> 0 | K36: =IF('CALENDARIO 2027'!I56="G",1,0) -> 1 | L36: =IF('CALENDARIO 2027'!I57="G",1,0) -> 0
B37: 35 | C37: 46552 | D37: 46558 | E37: =LEFT(IF('CALENDARIO 2027'!P53="G","JAVI · ","")&IF('CALENDARIO 2027'!P54="G","JOSE · ","")&IF('CALENDARIO 2027'!P55="G","JOSE LUIS · ","")&IF('CALENDARIO 2027'!P56="G","ALBERTO · ","")&IF('CALENDARIO 2027'!P57="G","MOLINERO · ",""),LEN(IF('CALENDARIO 2027'!P53="G","JAVI · ","")&IF('CALENDARIO 2027'!P54="G","JOSE · ","")&IF('CALENDARIO 2027'!P55="G","JOSE LUIS · ","")&IF('CALENDARIO 2027'!P56="G","ALBERTO · ","")&IF('CALENDARIO 2027'!P57="G","MOLINERO · ",""))-3) -> JOSE · MOLINERO | H37: =IF('CALENDARIO 2027'!P53="G",1,0) -> 0 | I37: =IF('CALENDARIO 2027'!P54="G",1,0) -> 1 | J37: =IF('CALENDARIO 2027'!P55="G",1,0) -> 0 | K37: =IF('CALENDARIO 2027'!P56="G",1,0) -> 0 | L37: =IF('CALENDARIO 2027'!P57="G",1,0) -> 1
B38: 36 | C38: 46559 | D38: 46565 | E38: =LEFT(IF('CALENDARIO 2027'!W53="G","JAVI · ","")&IF('CALENDARIO 2027'!W54="G","JOSE · ","")&IF('CALENDARIO 2027'!W55="G","JOSE LUIS · ","")&IF('CALENDARIO 2027'!W56="G","ALBERTO · ","")&IF('CALENDARIO 2027'!W57="G","MOLINERO · ",""),LEN(IF('CALENDARIO 2027'!W53="G","JAVI · ","")&IF('CALENDARIO 2027'!W54="G","JOSE · ","")&IF('CALENDARIO 2027'!W55="G","JOSE LUIS · ","")&IF('CALENDARIO 2027'!W56="G","ALBERTO · ","")&IF('CALENDARIO 2027'!W57="G","MOLINERO · ",""))-3) -> JOSE LUIS · ALBERTO | H38: =IF('CALENDARIO 2027'!W53="G",1,0) -> 0 | I38: =IF('CALENDARIO 2027'!W54="G",1,0) -> 0 | J38: =IF('CALENDARIO 2027'!W55="G",1,0) -> 1 | K38: =IF('CALENDARIO 2027'!W56="G",1,0) -> 1 | L38: =IF('CALENDARIO 2027'!W57="G",1,0) -> 0
B39: 37 | C39: 46566 | D39: 46572 | E39: =LEFT(IF('CALENDARIO 2027'!AD53="G","JAVI · ","")&IF('CALENDARIO 2027'!AD54="G","JOSE · ","")&IF('CALENDARIO 2027'!AD55="G","JOSE LUIS · ","")&IF('CALENDARIO 2027'!AD56="G","ALBERTO · ","")&IF('CALENDARIO 2027'!AD57="G","MOLINERO · ",""),LEN(IF('CALENDARIO 2027'!AD53="G","JAVI · ","")&IF('CALENDARIO 2027'!AD54="G","JOSE · ","")&IF('CALENDARIO 2027'!AD55="G","JOSE LUIS · ","")&IF('CALENDARIO 2027'!AD56="G","ALBERTO · ","")&IF('CALENDARIO 2027'!AD57="G","MOLINERO · ",""))-3) -> JAVI · JOSE | H39: =IF('CALENDARIO 2027'!AD53="G",1,0) -> 1 | I39: =IF('CALENDARIO 2027'!AD54="G",1,0) -> 1 | J39: =IF('CALENDARIO 2027'!AD55="G",1,0) -> 0 | K39: =IF('CALENDARIO 2027'!AD56="G",1,0) -> 0 | L39: =IF('CALENDARIO 2027'!AD57="G",1,0) -> 0
B40: 38 | C40: 46573 | D40: 46579 | E40: =LEFT(IF('CALENDARIO 2027'!G62="G","JAVI · ","")&IF('CALENDARIO 2027'!G63="G","JOSE · ","")&IF('CALENDARIO 2027'!G64="G","JOSE LUIS · ","")&IF('CALENDARIO 2027'!G65="G","ALBERTO · ","")&IF('CALENDARIO 2027'!G66="G","MOLINERO · ",""),LEN(IF('CALENDARIO 2027'!G62="G","JAVI · ","")&IF('CALENDARIO 2027'!G63="G","JOSE · ","")&IF('CALENDARIO 2027'!G64="G","JOSE LUIS · ","")&IF('CALENDARIO 2027'!G65="G","ALBERTO · ","")&IF('CALENDARIO 2027'!G66="G","MOLINERO · ",""))-3) -> JOSE LUIS · MOLINERO | H40: =IF('CALENDARIO 2027'!G62="G",1,0) -> 0 | I40: =IF('CALENDARIO 2027'!G63="G",1,0) -> 0 | J40: =IF('CALENDARIO 2027'!G64="G",1,0) -> 1 | K40: =IF('CALENDARIO 2027'!G65="G",1,0) -> 0 | L40: =IF('CALENDARIO 2027'!G66="G",1,0) -> 1
...
